Workbook

Sheet История VOR размеров
A1: Дата | B1: Код размера | C1: Код дефекта | D1: Наименование дефекта | E1: Контрмеры на этапе УП | F1: Оценка контрмер (OK/NG) | G1: Контрмеры на этапе СП | H1: Оценка контрмер (OK/NG)
A3: 45872 | B3: SP05 | C3: 321 | D3: =VLOOKUP(C3,'0080'!A$1:B$280,2,0) -> вулканизированная резина на плече | E3: -
A4: 45875 | B4: FS16 | C4: 521 | D4: =VLOOKUP(C4,'0080'!A$1:B$280,2,0) -> расслоение на плече | E4: на УП дефекта не было | F4: 16GH359XB -> 16AH366NA
A5: 45882 | B5: WS03 | C5: 210 | D5: =VLOOKUP(C5,'0080'!A$1:B$280,2,0) -> недопрессовка на стыке боковины | E5: 203 - акутальный контур в УП - ок. При повторном возникновении, необходима корректировка контура в зоне дефекта;
A6: 45883 | B6: AV08 | C6: 504 | D6: =VLOOKUP(C6,'0080'!A$1:B$280,2,0) -> поверхностный пузырь на основании борта | E6: 504 дефект , возник из-за повышенного давления на bead lock. Прошу провести дополнительное УП для корректировки пар-ров сборочной машины. | F6: изменения толко по тонкому чафферу , добавление каркаса
A7: 45893 | B7: SP05 | C7: 207 | D7: =VLOOKUP(C7,'0080'!A$1:B$280,2,0) -> недопрессовка по носку борта | E7: на УП дефекта не было | F7: PL-1T520QD1 → PL-1B520DD1
A8: 45894 | B8: SP05 | C8: 321 | D8: =VLOOKUP(C8,'0080'!A$1:B$280,2,0) -> вулканизированная резина на плече | E8: -
A9: 45897 | B9: SP09 | C9: 207 | D9: =VLOOKUP(C9,'0080'!A$1:B$280,2,0) -> недопрессовка по носку борта | E9: 783 дефект , шина входит в ПФ. 773/752 дефеккт - вулканизация изменила GT set. Дефект после выхода не повторялся. | F9: PL-1B735NQ3 → PL-1B735NQ4/Предотвращение 207 дефекта / 19AP420NA -> 19FH387XA
A10: 45903 | B10: WF03 | C10: 204 | D10: =VLOOKUP(C10,'0080'!A$1:B$280,2,0) -> недопрессовка по борту | E10: на УП дефекта не было | F10: Вакуум с 0 сек на 60 сек (против 204 дефекта)
A11: 45904 | B11: FS16 | C11: 207 | D11: =VLOOKUP(C11,'0080'!A$1:B$280,2,0) -> недопрессовка по носку борта | E11: на УП дефекта не было | F11: Использование чафера CC-T050L/RK-B7B6-6D4B → RK-B7B6-6E4B/PL-1B645NQ2→PL-1B645DQ4
A12: 45904 | B12: SP05 | C12: 773 | D12: =VLOOKUP(C12,'0080'!A$1:B$280,2,0) -> гребень по носку борта (облой) | E12: 406, 707 - проблема в нанесении допинга. Была свкулканизирована шина с сеткой и краской в бортовой зоне, для оценки течения резины. При осмотре образцов с данной шины никаких аномалий выявлено не было
A13: 45904 | B13: SP05 | C13: 752 | D13: =VLOOKUP(C13,'0080'!A$1:B$280,2,0) -> выход корда на основании борта | E13: -
A14: 45905 | B14: FS35 | C14: 553 | D14: =VLOOKUP(C14,'0080'!A$1:B$280,2,0) -> воздух в каркасе в области борта | E14: 522 (Расслоение на боковине) - изменили контур боковин, добавили верхнюю сквиджу на каркас, изменили параметры формовки вулканизации 20-80-80 -> 20-100-100. После всех изменений кол-во выхода дефекта значительно снизилось. | F14: Изменение параметров/использование тестового каркаса
A15: 45906 | B15: SP57 | C15: 773 | D15: =VLOOKUP(C15,'0080'!A$1:B$280,2,0) -> гребень по носку борта (облой) | E15: на УП дефекта не было/.На СП ремонтный дефект замечен на 6 шинах, после проверки центровки и настройки давления лопастей загрузчика на вулканизации, дефект исчез | F15: SS-041BB → SS-041BD | G15: Передан реквест на бортовые кольца, увеличение WWD =17.3→17.32
A16: 45908 | B16: FS04 | C16: 522 | D16: =VLOOKUP(C16,'0080'!A$1:B$280,2,0) -> расслоение на боковине | E16: 522 расслоение на боковине - внесли контрмеры как на размере FS35: обновленный контур боковин (убрали провал по центру), добавили верхнюю сквиджу. Мониторинг в расширенном УП. | F16: изм.конт.боковин ST-001AB → ST-001AD
A17: 45909 | B17: SP05 | C17: 215 | D17: =VLOOKUP(C17,'0080'!A$1:B$280,2,0) -> недопрессовка на короне - PXR | E17: на УП дефекта не было
A18: 45910 | B18: EC27 | C18: 207 | D18: =VLOOKUP(C18,'0080'!A$1:B$280,2,0) -> недопрессовка по носку борта | E18: 207 дефект - находится на стыке каркаса. Дефект ремонтный , фото дефекта отсутствует. При старте производства оценить влияние положения боковин на дефект. При необходимости доработать контур боковин. | F18: использование д/ф от Tianjin RB17-3
A19: 45911 | B19: AV27 | C19: 207 | D19: =VLOOKUP(C19,'0080'!A$1:B$280,2,0) -> недопрессовка по носку борта | E19: на УП дефекта не было
A20: 45911 | B20: EC05 | C20: 773 | D20: =VLOOKUP(C20,'0080'!A$1:B$280,2,0) -> гребень по носку борта (облой) | E20: на УП дефекта не было | F20: Против 773/752 + сработка стоков каркаса (оригинальный) кольца WWD +0.02 (КАРКАС ОРИГИНАЛЬНЫЙ)
A21: 45911 | B21: IC04 | C21: 781 | D21: =VLOOKUP(C21,'0080'!A$1:B$280,2,0) -> смещение края "протектор/боковина" | E21: -
A22: 45912 | B22: AV26 | C22: 207 | D22: =VLOOKUP(C22,'0080'!A$1:B$280,2,0) -> недопрессовка по носку борта | E22: 207 дефект (недопрессовка по носку борта): Изменения со стороны TS не вносились, тк дефект в большинстве своем ремонтный. Как корректирущие действия можно рассмотреть измение сета боковин на -2мм внутрь (параметр SW2 -2мм, до 0 можно приспустить), что должно дать положительный эффект.
A23: 45919 | B23: FS14 | C23: 810 | D23: =VLOOKUP(C23,'0080'!A$1:B$280,2,0) -> загрязнение пресс-формы (борт) | E23: -
A24: 45921 | B24: FS05 | C24: 504 | D24: =VLOOKUP(C24,'0080'!A$1:B$280,2,0) -> поверхностный пузырь на основании борта | E24: на УП дефекта не было | F24: ST-004AA→ST004AB
A25: 45922 | B25: SP45 | C25: 318 | D25: =VLOOKUP(C25,'0080'!A$1:B$280,2,0) -> другие (снаружи) | E25: -
A26: 45930 | B26: SP45 | C26: 782 | D26: =VLOOKUP(C26,'0080'!A$1:B$280,2,0) -> облой на протекторе | E26: 783-шина входит в ПФ с запасом. | F26: Актуализация параметров
A27: 45932 | B27: AV39 | C27: 207 | D27: =VLOOKUP(C27,'0080'!A$1:B$280,2,0) -> недопрессовка по носку борта | E27: на УП дефекта не было | F27: переход на тонкий чафер 1.0мм
A28: 45932 | B28: EC05 | C28: 207 | D28: =VLOOKUP(C28,'0080'!A$1:B$280,2,0) -> недопрессовка по носку борта | E28: на УП дефекта не было | F28: Сработка неиспользуемого стока
A29: 45933 | B29: EC06 | C29: 581 | D29: =VLOOKUP(C29,'0080'!A$1:B$280,2,0) -> пузырь в гермослое | E29: на УП дефекта не было | F29: 15GH356XA → 15EXR345/4
A30: 45933 | B30: EC25 | C30: 773 | D30: =VLOOKUP(C30,'0080'!A$1:B$280,2,0) -> гребень по носку борта (облой) | E30: 773: производили настройку загрузчика сырой шины(уменьшение давления, настройка лопастей), после настройки дефект не проявлялся. | F30: 15GH378XB → 15GH373XB
A31: 45933 | B31: WF03 | C31: 581 | D31: =VLOOKUP(C31,'0080'!A$1:B$280,2,0) -> пузырь в гермослое | E31: 581 дефект , возник на стыке гермослоя, из-за отсутствия вакуума на каркасном барабане.Производили настройку наложения гермослоя. | F31: изм. гермослой IL-AZ325-13 на IL-AZ325-15
A32: 45935 | B32: EC36 | C32: 207 | D32: =VLOOKUP(C32,'0080'!A$1:B$280,2,0) -> недопрессовка по носку борта | E32: на УП дефекта не было | F32: PL-1B680ND1→PL-1B680DD1
A33: 45936 | B33: EC36 | C33: 581 | D33: =VLOOKUP(C33,'0080'!A$1:B$280,2,0) -> #N/A | E33: на УП дефекта не было | F33: PL-1B680DD1 → PL-1B680DD2 | G33: Новый каркас PL-1B680DD1→DD2 Смещение + уменьшение SQ. | H33: OK
A34: 45946 | B34: AW28 | C34: 207 | D34: =VLOOKUP(C34,'0080'!A$1:B$280,2,0) -> недопрессовка по носку борта | E34: на УП дефекта не было | F34: 18EXR375-> 18GH378XA
A35: 45947 | B35: AV38 | C35: 521 | D35: =VLOOKUP(C35,'0080'!A$1:B$280,2,0) -> расслоение на плече | E35: 521- дефект проявился на шве протектора , из-за отсутствия нахлеста минибоковин получили полость воздуха на готовой шине. Для конструкции SOT очень важно не допускать пустот в зоне стыка протектора. | F35: сработка остатка ТТ с изменением параметров
A36: 45947 | B36: WF03 | C36: 719 | D36: =VLOOKUP(C36,'0080'!A$1:B$280,2,0) -> несоответствующий ремонт (Сборка) | E36: -
A37: 45948 | B37: SP49 | C37: 581 | D37: =VLOOKUP(C37,'0080'!A$1:B$280,2,0) -> пузырь в гермослое | E37: на УП дефекта не было | F37: изменение ТОР и SW
A38: 45949 | B38: AV19 | C38: 782 | D38: =VLOOKUP(C38,'0080'!A$1:B$280,2,0) -> облой на протекторе | E38: на УП дефекта не было/контур сырой шины vs STLO mold - OK | F38: изменения толко по тонкому чафферу , добавление каркаса
A39: 45949 | B39: AV37 | C39: 207 | D39: =VLOOKUP(C39,'0080'!A$1:B$280,2,0) -> недопрессовка по носку борта | E39: на УП дефекта не было | F39: Тестирование диафрагмы RUNTONG
A40: 45949 | B40: WF03 | C40: 783 | D40: =VLOOKUP(C40,'0080'!A$1:B$280,2,0) -> облой на боковине | E40: 783 (облой на боковине) - шина с запасом лезет в пресс-форму, дефект присутствует из-за несоответствия пресс-формы. | F40: изм.конт.боковин ST-066AB → ST-066AC
A41: 45953 | B41: AV48 | C41: 207 | D41: =VLOOKUP(C41,'0080'!A$1:B$280,2,0) -> недопрессовка по носку борта | E41: Для предотвращения возникновения 207 дефекта использовалась боковина ST-126BD. Результат - ОК | F41: 18FH406XAI → 18FH369XB /Актуализация сборочных параметров/ST-126BC→ ST-126BD | G41: КАРКАС 0.6 SQ QN3 Проработка новой матрицы (если BC sw не сработана)
...

Sheet Содержание
A1: Содержание:
B4: 200 | C4: недопрессовка на короне - PSR | H4: 3
B5: 201 | C5: недопрессовка на плече | H5: 4
B6: 202 | C6: недопрессовка на декор.линии | H6: 5
B7: 203 | C7: недопрессовка на боковине | H7: 6
B8: 204 | C8: недопрессовка по борту | H8: 7
B9: 205 | C9: недопрессовка на пятке | H9: 8
B10: 206 | C10: недопрессовка на основании | H10: 9
B11: 207 | C11: недопрессовка по носку борта | H11: 10
B12: 208 | C12: недопрессовка на внутренней поверхности | H12: 11
B13: 209 | C13: недопрессовка на стыке протектора - PSR | H13: 12
B14: 210 | C14: недопрессовка на стыке боковины | H14: 13
B15: 211 | C15: недопрессовка из-за силикона | H15: 14
... B119: 794 | C119: волнообразная неровность на поверхности боковины | H119: 118

Sheet 3
A1: 200 недопрессовка на короне - PSR
A2: Фото дефекта (пример) | F2: Причины дефекта | L2: Меры, которые необходимо принять | Q2: Комментарии
F5: Спецификация
F9: Участок резки и экструзии
F19: Участок сборки и вулканизации

Sheet 4
A1: 201 недопрессовка на плече
A2: Фото дефекта (пример) | F2: Причины дефекта | L2: Меры, которые необходимо принять | Q2: Комментарии
F5: Спецификация
F9: Участок резки и экструзии
F19: Участок сборки и вулканизации

Sheet 5
A1: 202 недопрессовка на декор.линии
A2: Фото дефекта (пример) | F2: Причины дефекта | L2: Меры, которые необходимо принять | Q2: Комментарии
F5: Спецификация
F9: Участок резки и экструзии
F19: Участок сборки и вулканизации

Sheet 6
A1: 203 недопрессовка на боковине
A2: Фото дефекта (пример) | F2: Причины дефекта | L2: Меры, которые необходимо принять | Q2: Комментарии
F5: Спецификация
F9: Участок резки и экструзии
F19: Участок сборки и вулканизации | H19: 1)недостаточный объем резины на месте дефекта 2) отсутствие необходимых вент отверстий на месте дефекта | L19: 1) Проверить SW на соответствие толщин со спецификацией. Обозначить дефект на сыром контуре SW, изменить толщину SW на месте дефекта

Sheet 7
A1: 204 недопрессовка по борту
A2: Фото дефекта (пример) | F2: Причины дефекта | L2: Меры, которые необходимо принять | Q2: Комментарии
F5: Спецификация
F9: Участок резки и экструзии
F19: Участок сборки и вулканизации

Sheet 8
A1: 205 недопрессовка на пятке
A2: Фото дефекта (пример) | F2: Причины дефекта | L2: Меры, которые необходимо принять | Q2: Комментарии
F5: Спецификация
F9: Участок резки и экструзии
F19: Участок сборки и вулканизации

Sheet 9
A1: 206 недопрессовка на основании
A2: Фото дефекта (пример) | F2: Причины дефекта | L2: Меры, которые необходимо принять | Q2: Комментарии
F5: Спецификация
F9: Участок резки и экструзии
F19: Участок сборки и вулканизации

Sheet 10
A1: 207 недопрессовка по носку борта
A2: Фото дефекта (пример) | F2: Причины дефекта | L2: Меры, которые необходимо принять | Q2: Комментарии
F5: Спецификация
F9: Участок резки и экструзии
F19: Участок сборки и вулканизации | H19: 1)недостаточный объем резины под бортом 2) некорректная установка боковин на сборке, AGS =5mm и более | L19: 1) Увеличить обьем резины под бортом за счет добавления доп SQ или увеличения толщин Ags в SW 2) установить боковины по спецификации, проверить смещение после наложения предсборки каркаса с гермослоем на сборке, отрегулировать соотношение скоростей и расстояние отодвижения конвейера

Sheet 11
A1: 208 недопрессовка на внутренней поверхности
A2: Фото дефекта (пример) | F2: Причины дефекта | L2: Меры, которые необходимо принять | Q2: Комментарии
F5: Спецификация
F9: Участок резки и экструзии
F19: Участок сборки и вулканизации

Sheet 12
A1: 209 недопрессовка на стыке протектора - PSR
A2: Фото дефекта (пример) | F2: Причины дефекта | L2: Меры, которые необходимо принять | Q2: Комментарии
F5: Спецификация
F9: Участок резки и экструзии
F19: Участок сборки и вулканизации

Sheet 13
A1: 210 недопрессовка на стыке боковины
A2: Фото дефекта (пример) | F2: Причины дефекта | L2: Меры, которые необходимо принять | Q2: Комментарии
F5: Спецификация
F9: Участок резки и экструзии
F19: Участок сборки и вулканизации | H19: Недостаточная величина стыка боковин

Sheet 14
A1: 211 недопрессовка из-за силикона
A2: Фото дефекта (пример) | F2: Причины дефекта | L2: Меры, которые необходимо принять | Q2: Комментарии
F5: Спецификация
F9: Участок резки и экструзии
F19: Участок сборки и вулканизации | H19: Проверить на загрязнение силиконом пресс-формы | L19: Устранить загрязнение

Sheet 15
A1: 212 недопрессовка боковины из-за забитых воздухоотводящих отверстий
A2: Фото дефекта (пример) | F2: Причины дефекта | L2: Меры, которые необходимо принять | Q2: Комментарии
F5: Спецификация
F9: Участок резки и экструзии
F19: Участок сборки и вулканизации

Sheet 16
A1: 213 недопрессовка по краям шашек протектора
A2: Фото дефекта (пример) | F2: Причины дефекта | L2: Меры, которые необходимо принять | Q2: Комментарии
F5: Спецификация
F9: Участок резки и экструзии
F19: Участок сборки и вулканизации

Sheet 17
A1: 214 недопрессовка буквенных обозначений
A2: Фото дефекта (пример) | F2: Причины дефекта | L2: Меры, которые необходимо принять | Q2: Комментарии
F5: Спецификация
F9: Участок резки и экструзии
F19: Участок сборки и вулканизации | H19: Недостаток объема резины , отсутствие вент отверстий в зоне дефекта | L19: Проверка контура боковин , проверка наличия вент отвертий в зоне дефекта

Sheet 18
A1: 215 недопрессовка на короне - PXR
A2: Фото дефекта (пример) | F2: Причины дефекта | L2: Меры, которые необходимо принять | Q2: Комментарии
F5: Спецификация
F9: Участок резки и экструзии
F19: Участок сборки и вулканизации

Sheet 19
A1: 216 недопрессовка на стыке протектора - PXR
A2: Фото дефекта (пример) | F2: Причины дефекта | L2: Меры, которые необходимо принять | Q2: Комментарии
F5: Спецификация
F9: Участок резки и экструзии
F19: Участок сборки и вулканизации

Sheet 20
A1: 217 ямки между блоками протектора/недопрессовки
A2: Фото дефекта (пример) | F2: Причины дефекта | L2: Меры, которые необходимо принять | Q2: Комментарии
F5: Спецификация
F9: Участок резки и экструзии
F19: Участок сборки и вулканизации

Sheet 21
A1: 400 трещина на плече
A2: Фото дефекта (пример) | F2: Причины дефекта | L2: Меры, которые необходимо принять | Q2: Комментарии
F5: Спецификация
F9: Участок резки и экструзии
F19: Участок сборки и вулканизации

Sheet 22
A1: 401 трещина на боковине
A2: Фото дефекта (пример) | F2: Причины дефекта | L2: Меры, которые необходимо принять | Q2: Комментарии
F5: Спецификация
F9: Участок резки и экструзии
F19: Участок сборки и вулканизации

Sheet 23
A1: 402 трещина на бортовом кольце
A2: Фото дефекта (пример) | F2: Причины дефекта | L2: Меры, которые необходимо принять | Q2: Комментарии
F5: Спецификация
F9: Участок резки и экструзии
F19: Участок сборки и вулканизации

Sheet 24
A1: 403 трещина корда
A2: Фото дефекта (пример) | F2: Причины дефекта | L2: Меры, которые необходимо принять | Q2: Комментарии
F5: Спецификация
F9: Участок резки и экструзии
F19: Участок сборки и вулканизации

Sheet 25
A1: 404 трещина на гермослое
A2: Фото дефекта (пример) | F2: Причины дефекта | L2: Меры, которые необходимо принять | Q2: Комментарии
F5: Спецификация
F9: Участок резки и экструзии
F19: Участок сборки и вулканизации | H19: 1)Некачественный рез гермослоя на сборке. 2)Некачественный стык гермослоя. 3)Черезмерное количество нанесенного допинга | L19: Произвести проверку по всем пунктам со стыком гермослоя

Sheet 26
A1: 405 др. трещины
A2: Фото дефекта (пример) | F2: Причины дефекта | L2: Меры, которые необходимо принять | Q2: Комментарии
F5: Спецификация
F9: Участок резки и экструзии
F19: Участок сборки и вулканизации

Sheet 27
A1: 406 трещина по носку борта
A2: Фото дефекта (пример) | F2: Причины дефекта | L2: Меры, которые необходимо принять | Q2: Комментарии
F5: Спецификация
F9: Участок резки и экструзии
F19: Участок сборки и вулканизации | H19: 1)Большой объем резины в носке борта 2) Проблемы в нанесении допинга | L19: 1)проверить натяжение каркаса в шине 2)проверить настройки нанесения допинга

Sheet 28
A1: 407 трещина на ручном стыке каркаса
A2: Фото дефекта (пример) | F2: Причины дефекта | L2: Меры, которые необходимо принять | Q2: Комментарии
F5: Спецификация
F9: Участок резки и экструзии
F19: Участок сборки и вулканизации

Sheet 29
A1: 500 поверхностный пузырь на короне - PSR
A2: Фото дефекта (пример) | F2: Причины дефекта | L2: Меры, которые необходимо принять | Q2: Комментарии
F5: Спецификация
F9: Участок резки и экструзии
F19: Участок сборки и вулканизации

Sheet 30
A1: 501 поверхностный пузырь на плече
A2: Фото дефекта (пример) | F2: Причины дефекта | L2: Меры, которые необходимо принять | Q2: Комментарии
F5: Спецификация
F9: Участок резки и экструзии
F19: Участок сборки и вулканизации

Sheet 31
A1: 502 поверхностный пузырь на боковине
A2: Фото дефекта (пример) | F2: Причины дефекта | L2: Меры, которые необходимо принять | Q2: Комментарии
F5: Спецификация
F9: Участок резки и экструзии
F19: Участок сборки и вулканизации

Sheet 32
A1: 503 поверхностный пузырь в зоне борта
A2: Фото дефекта (пример) | F2: Причины дефекта | L2: Меры, которые необходимо принять | Q2: Комментарии
F5: Спецификация
F9: Участок резки и экструзии
F19: Участок сборки и вулканизации | H19: 1) Проверить месторасположение дефекта взависимости от вакумных отверстий 2)плохая прикатка USR роликами 3)плохая прикатка SW на формующем барабане | L19: 1) В зависимости от формы боковин подобрать бандаж и спейсер, чтобы исключить неровности и резкие перепады после наложения боковин. 2)Необходимо проверить и по необходимости настроить прикатку USR роликов в зоне дефекта. 3)Настроить midle stop прикатку в зоне дефекта.

Sheet 33
A1: 504 поверхностный пузырь на основании борта
A2: Фото дефекта (пример) | F2: Причины дефекта | L2: Меры, которые необходимо принять | Q2: Комментарии
F5: Спецификация
F9: Участок резки и экструзии
F19: Участок сборки и вулканизации | H19: Недостаток объема резины,неправильное расположение SQ на каркасе, некачественный стык CCh, дефекты на кольце, наненсение допинга на борт. | L19: Добавить или расширить BSQ каркаса, проверить стыки IL, ССh ,SW

Sheet 34
A1: 520 расслоение на короне - PSR
A2: Фото дефекта (пример) | F2: Причины дефекта | L2: Меры, которые необходимо принять | Q2: Комментарии
F5: Спецификация
F9: Участок резки и экструзии
F19: Участок сборки и вулканизации

Sheet 35
A1: 521 расслоение на плече
A2: Фото дефекта (пример) | F2: Причины дефекта | L2: Меры, которые необходимо принять | Q2: Комментарии
F5: Спецификация
F9: Участок резки и экструзии
F19: Участок сборки и вулканизации | H19: Проверить прикатку в зоне дефекта

Sheet 36
A1: 522 расслоение на боковине
A2: Фото дефекта (пример) | F2: Причины дефекта | L2: Меры, которые необходимо принять | Q2: Комментарии
F5: Спецификация
F9: Участок резки и экструзии
F19: Участок сборки и вулканизации

Sheet 37
A1: 523 расслоение в зоне борта
A2: Фото дефекта (пример) | F2: Причины дефекта | L2: Меры, которые необходимо принять | Q2: Комментарии
F5: Спецификация
F9: Участок резки и экструзии
F19: Участок сборки и вулканизации

Sheet 38
A1: 524 расслоение на стыке боковины
A2: Фото дефекта (пример) | F2: Причины дефекта | L2: Меры, которые необходимо принять | Q2: Комментарии
F5: Спецификация
F9: Участок резки и экструзии
F19: Участок сборки и вулканизации

Sheet 39
A1: 525 др. расслоение
A2: Фото дефекта (пример) | F2: Причины дефекта | L2: Меры, которые необходимо принять | Q2: Комментарии
F5: Спецификация
F9: Участок резки и экструзии
F19: Участок сборки и вулканизации

Sheet 40
A1: 550 воздух в каркасе в области короны
A2: Фото дефекта (пример) | F2: Причины дефекта | L2: Меры, которые необходимо принять | Q2: Комментарии
F5: Спецификация
F9: Участок резки и экструзии
F19: Участок сборки и вулканизации

Sheet 41
A1: 551 воздух в каркасе в области плеча
A2: Фото дефекта (пример) | F2: Причины дефекта | L2: Меры, которые необходимо принять | Q2: Комментарии
F5: Спецификация
F9: Участок резки и экструзии
F19: Участок сборки и вулканизации

Sheet 42
A1: 552 воздух в каркасе на боковине
A2: Фото дефекта (пример) | F2: Причины дефекта | L2: Меры, которые необходимо принять | Q2: Комментарии
F5: Спецификация
F9: Участок резки и экструзии
F19: Участок сборки и вулканизации | H19: 1)Неправильно подобранный бандаж и спейсер на KB барабане 2)плохая прикатка USR роликами 3)плохая прикатка SW на формующем барабане | L19: 1) В зависимости от формы боковин подобрать бандаж и спейсер, чтобы исключить неровности и резкие перепады после наложения боковин. 2)Необходимо проверить и по необходимости настроить прикатку USR роликов в зоне дефекта. 3)Настроить midle stop прикатку в зоне дефекта.

Sheet 43
A1: 553 воздух в каркасе в области борта

Sheet 44
A1: 580 воздух на текстильной бортовой ленте

Sheet 45
A1: 581 пузырь в гермослое
A2: Фото дефекта (пример) | F2: Причины дефекта | L2: Меры, которые необходимо принять | Q2: Комментарии
F5: Спецификация
F9: Участок резки и экструзии
F19: Участок сборки и вулканизации

Sheet 46
A1: 582 воздух в др. слоях

Sheet 47
A1: 583 пузырь на буквенном обозначении
A2: Фото дефекта (пример) | F2: Причины дефекта | L2: Меры, которые необходимо принять | Q2: Комментарии
F5: Спецификация
F9: Участок резки и экструзии
F19: Участок сборки и вулканизации

Sheet 48
A1: 584 отслоение гермослоя
A2: Фото дефекта (пример) | F2: Причины дефекта | L2: Меры, которые необходимо принять | Q2: Комментарии
F5: Спецификация
F9: Участок резки и экструзии
F19: Участок сборки и вулканизации

Sheet 49
A1: 585 поверхностный пузырь на короне - PXR
A2: Фото дефекта (пример) | F2: Причины дефекта | L2: Меры, которые необходимо принять | Q2: Комментарии
F5: Спецификация
F9: Участок резки и экструзии
F19: Участок сборки и вулканизации | H19: Недостаточная прикатка TT, неравномерная намотка спирального слоя.

Sheet 50
A1: 586 расслоение на короне - PXR
A2: Фото дефекта (пример) | F2: Причины дефекта | L2: Меры, которые необходимо принять | Q2: Комментарии
F5: Спецификация
F9: Участок резки и экструзии
F19: Участок сборки и вулканизации

Sheet 51
A1: 700 трещина стыка гермослоя
A2: Фото дефекта (пример) | F2: Причины дефекта | L2: Меры, которые необходимо принять | Q2: Комментарии
F5: Спецификация
F9: Участок резки и экструзии
F19: Участок сборки и вулканизации

Sheet 52
A1: 701 открытый стык каркаса (на сборке)
A2: Фото дефекта (пример) | F2: Причины дефекта | L2: Меры, которые необходимо принять | Q2: Комментарии
F5: Спецификация
F9: Участок резки и экструзии
F19: Участок сборки и вулканизации

Sheet 53
A1: 702 утолщение стыка гермослоя
A2: Фото дефекта (пример) | F2: Причины дефекта | L2: Меры, которые необходимо принять | Q2: Комментарии
F5: Спецификация
F9: Участок резки и экструзии
F19: Участок сборки и вулканизации

Sheet 54
A1: 703 выход корда по внутренней поверхности

Sheet 55
A1: 704 смещение бортового наполнителя
A2: Фото дефекта (пример) | F2: Причины дефекта | L2: Меры, которые необходимо принять | Q2: Комментарии
F5: Спецификация
F9: Участок резки и экструзии
F19: Участок сборки и вулканизации

Sheet 56
A1: 705 выход проволоки на внутренний слой
A2: Фото дефекта (пример) | F2: Причины дефекта | L2: Меры, которые необходимо принять | Q2: Комментарии
F5: Спецификация
F9: Участок резки и экструзии
F19: Участок сборки и вулканизации

Sheet 57
A1: 706 утолщение на внутренней поверхности
A2: Фото дефекта (пример) | F2: Причины дефекта | L2: Меры, которые необходимо принять | Q2: Комментарии
F5: Спецификация
F9: Участок резки и экструзии
F19: Участок сборки и вулканизации

Sheet 58
A1: 707 содранный гермослой
F5: Спецификация
F9: Участок резки и экструзии
F19: Участок сборки и вулканизации | H19: Посторонние включения в материале

Sheet 59
A1: 708 неоднородность по толщине внутренней поверхности
A2: Фото дефекта (пример) | F2: Причины дефекта | L2: Меры, которые необходимо принять | Q2: Комментарии
F5: Спецификация
F9: Участок резки и экструзии
F19: Участок сборки и вулканизации | H19: Посторонние включения в материале

Sheet 60
A1: 709 выход нити компонента в зоне стыка
A2: Фото дефекта (пример) | F2: Причины дефекта | L2: Меры, которые необходимо принять | Q2: Комментарии
F5: Спецификация
F9: Участок резки и экструзии
F19: Участок сборки и вулканизации

Sheet 61
A1: 710 открытый стык гермослоя
A2: Фото дефекта (пример) | F2: Причины дефекта | L2: Меры, которые необходимо принять | Q2: Комментарии
F5: Спецификация
F9: Участок резки и экструзии
F19: Участок сборки и вулканизации

Sheet 62
A1: 711 открытый стык боковины
A2: Фото дефекта (пример) | F2: Причины дефекта | L2: Меры, которые необходимо принять | Q2: Комментарии
F5: Спецификация
F9: Участок резки и экструзии
F19: Участок сборки и вулканизации

Sheet 63
A1: 712 открытый стык бортового наполнителя
A2: Фото дефекта (пример) | F2: Причины дефекта | L2: Меры, которые необходимо принять | Q2: Комментарии
F5: Спецификация
F9: Участок резки и экструзии
F19: Участок сборки и вулканизации

Sheet 64
A1: 713 шероховатый гермослой
A2: Фото дефекта (пример) | F2: Причины дефекта | L2: Меры, которые необходимо принять | Q2: Комментарии
F5: Спецификация
F9: Участок резки и экструзии
F19: Участок сборки и вулканизации

Sheet 65
A1: 714 складки на гермослое
A2: Фото дефекта (пример) | F2: Причины дефекта | L2: Меры, которые необходимо принять | Q2: Комментарии
F5: Спецификация
F9: Участок резки и экструзии
F19: Участок сборки и вулканизации | H19: Проблема в наложении материалов на барабан KB | L19: Проверить гермослой на КБ барабане после наложения предсборки,на наличие складок и деформаций, отрегулировать соотношение скоростей конвейера и барабана, так же настроить отодвижение конвейера.

Sheet 66
A1: 715 складки на каркасе (продольная, как стык)
A2: Фото дефекта (пример) | F2: Причины дефекта | L2: Меры, которые необходимо принять | Q2: Комментарии
F5: Спецификация
F9: Участок резки и экструзии
F19: Участок сборки и вулканизации

Sheet 67
A1: 716 другие складки

Sheet 68
A1: 717 содранный C.Ch
A2: Фото дефекта (пример) | F2: Причины дефекта | L2: Меры, которые необходимо принять | Q2: Комментарии
F5: Спецификация
F9: Участок резки и экструзии
F19: Участок сборки и вулканизации

Sheet 69
A1: 718 складка брекера
A2: Фото дефекта (пример) | F2: Причины дефекта | L2: Меры, которые необходимо принять | Q2: Комментарии
F5: Спецификация
F9: Участок резки и экструзии
F19: Участок сборки и вулканизации

Sheet 70
A1: 719 несоответствующий ремонт (Сборка)
A2: Фото дефекта (пример) | F2: Причины дефекта | L2: Меры, которые необходимо принять | Q2: Комментарии
F5: Спецификация
F9: Участок резки и экструзии
F19: Участок сборки и вулканизации

Sheet 71
A1: 720 загиб брекера

Sheet 72
A1: 721 несоответствия брекера
A2: Фото дефекта (пример) | F2: Причины дефекта | L2: Меры, которые необходимо принять | Q2: Комментарии
F5: Спецификация
F9: Участок резки и экструзии
F19: Участок сборки и вулканизации

Sheet 73
A1: 722 спаренный корд
A2: Фото дефекта (пример) | F2: Причины дефекта | L2: Меры, которые необходимо принять | Q2: Комментарии
F5: Спецификация
F9: Участок резки и экструзии
F19: Участок сборки и вулканизации

Sheet 74
A1: 723 деформация шины из-за перетяжки спир. слоя
A2: Фото дефекта (пример) | F2: Причины дефекта | L2: Меры, которые необходимо принять | Q2: Комментарии
F5: Спецификация
F9: Участок резки и экструзии
F19: Участок сборки и вулканизации

Sheet 75
A1: 724 другие несоответствия внутренней поверхности
A2: Фото дефекта (пример) | F2: Причины дефекта | L2: Меры, которые необходимо принять | Q2: Комментарии
F5: Спецификация
F9: Участок резки и экструзии
F19: Участок сборки и вулканизации

Sheet 76
A1: 725 складки на каркасе (поперечная)
A2: Фото дефекта (пример) | F2: Причины дефекта | L2: Меры, которые необходимо принять | Q2: Комментарии
F5: Спецификация
F9: Участок резки и экструзии
F19: Участок сборки и вулканизации

Sheet 77
A1: 726 открытый стык каркаса (на предпроцессах)
A2: Фото дефекта (пример) | F2: Причины дефекта | L2: Меры, которые необходимо принять | Q2: Комментарии
F5: Спецификация
F9: Участок резки и экструзии
F19: Участок сборки и вулканизации

Sheet 78
A1: 727 диагональный стык каркаса
A2: Фото дефекта (пример) | F2: Причины дефекта | L2: Меры, которые необходимо принять | Q2: Комментарии
F5: Спецификация
F9: Участок резки и экструзии
F19: Участок сборки и вулканизации

Sheet 79
A1: 740 смещение центральной линии протектора
A2: Фото дефекта (пример) | F2: Причины дефекта | L2: Меры, которые необходимо принять | Q2: Комментарии
F5: Спецификация
F9: Участок резки и экструзии
F19: Участок сборки и вулканизации

Sheet 80
A1: 741 трещина, скол короны - PSR
A2: Фото дефекта (пример) | F2: Причины дефекта | L2: Меры, которые необходимо принять | Q2: Комментарии
F5: Спецификация
F9: Участок резки и экструзии
F19: Участок сборки и вулканизации

Sheet 81
A1: 742 уступы по короне, горизонтальное смещение
A2: Фото дефекта (пример) | F2: Причины дефекта | L2: Меры, которые необходимо принять | Q2: Комментарии
F5: Спецификация
F9: Участок резки и экструзии
F19: Участок сборки и вулканизации

Sheet 82
A1: 743 деформация короны
A2: Фото дефекта (пример) | F2: Причины дефекта | L2: Меры, которые необходимо принять | Q2: Комментарии
F5: Спецификация
F9: Участок резки и экструзии
F19: Участок сборки и вулканизации

Sheet 83
A1: 744 закус короны
A2: Фото дефекта (пример) | F2: Причины дефекта | L2: Меры, которые необходимо принять | Q2: Комментарии
F5: Спецификация
F9: Участок резки и экструзии
F19: Участок сборки и вулканизации

Sheet 84
A1: 745 несоответствие ID линий
A2: Фото дефекта (пример) | F2: Причины дефекта | L2: Меры, которые необходимо принять | Q2: Комментарии
F5: Спецификация
F9: Участок резки и экструзии
F19: Участок сборки и вулканизации

Sheet 85
A1: 746 загрязнение ID линий

Sheet 86
A1: 747 наклон блоков шашек короны

Sheet 87
A1: 748 расширение ламелей
A2: Фото дефекта (пример) | F2: Причины дефекта | L2: Меры, которые необходимо принять | Q2: Комментарии
F5: Спецификация
F9: Участок резки и экструзии
F19: Участок сборки и вулканизации

Sheet 88
A1: 749 следы от перфорирующего устройства

Sheet 89
A1: 750 несоответствие центральной линии
A2: Фото дефекта (пример) | F2: Причины дефекта | L2: Меры, которые необходимо принять | Q2: Комментарии
F5: Спецификация
F9: Участок резки и экструзии
F19: Участок сборки и вулканизации

Sheet 90
A1: 751 несоответствие маркировки протектора

Sheet 91
A1: 752 выход корда на основании борта
A2: Фото дефекта (пример) | F2: Причины дефекта | L2: Меры, которые необходимо принять | Q2: Комментарии
F5: Спецификация
F9: Участок резки и экструзии
F19: Участок сборки и вулканизации

Sheet 92
A1: 753 слипание ламелей (PXR)
A2: Фото дефекта (пример) | F2: Причины дефекта | L2: Меры, которые необходимо принять | Q2: Комментарии
F5: Спецификация
F9: Участок резки и экструзии
F19: Участок сборки и вулканизации

Sheet 93
A1: 754 сколы/трещины в области ламели (PXR)
A2: Фото дефекта (пример) | F2: Причины дефекта | L2: Меры, которые необходимо принять | Q2: Комментарии
F5: Спецификация
F9: Участок резки и экструзии
F19: Участок сборки и вулканизации

Sheet 94
A1: 770 неправильная форма бортового кольца
A2: Фото дефекта (пример) | F2: Причины дефекта | L2: Меры, которые необходимо принять | Q2: Комментарии
F5: Спецификация
F9: Участок резки и экструзии
F19: Участок сборки и вулканизации

Sheet 95
A1: 771 деформация борта
A2: Фото дефекта (пример) | F2: Причины дефекта | L2: Меры, которые необходимо принять | Q2: Комментарии
F5: Спецификация
F9: Участок резки и экструзии
F19: Участок сборки и вулканизации

Sheet 96
A1: 772 неправильная толщина борта
A2: Фото дефекта (пример) | F2: Причины дефекта | L2: Меры, которые необходимо принять | Q2: Комментарии
F5: Спецификация
F9: Участок резки и экструзии
F19: Участок сборки и вулканизации

Sheet 97
A1: 773 гребень по носку борта (облой)
A2: Фото дефекта (пример) | F2: Причины дефекта | L2: Меры, которые необходимо принять | Q2: Комментарии
F5: Спецификация
F9: Участок резки и экструзии
F19: Участок сборки и вулканизации | H19: 1)Излишний объем резины под бортом 2) неровная посадка сырой шины на вулканизации 3) сырая шина долго хранилась в транспортировочной тележке | L19: 1) уменьшить толщину AGS( см. результат BFF) 2) отрегулировать положение загрузчика, изменить положение B спейсера

Sheet 98
A1: 774 смещение центра бортового кольца
A2: Фото дефекта (пример) | F2: Причины дефекта | L2: Меры, которые необходимо принять | Q2: Комментарии
F5: Спецификация
F9: Участок резки и экструзии
F19: Участок сборки и вулканизации

Sheet 99
A1: 775 выход корда в зоне борта
A2: Фото дефекта (пример) | F2: Причины дефекта | L2: Меры, которые необходимо принять | Q2: Комментарии
F5: Спецификация
F9: Участок резки и экструзии
F19: Участок сборки и вулканизации

Sheet 100
A1: 776 трещина, скол борта
A2: Фото дефекта (пример) | F2: Причины дефекта | L2: Меры, которые необходимо принять | Q2: Комментарии
F5: Спецификация
F9: Участок резки и экструзии
F19: Участок сборки и вулканизации

Sheet 101
A1: 777 излом борта по внутренней поверхности
A2: Фото дефекта (пример) | F2: Причины дефекта | L2: Меры, которые необходимо принять | Q2: Комментарии
F5: Спецификация
F9: Участок резки и экструзии
F19: Участок сборки и вулканизации

Sheet 102
A1: 778 ступенчатость бортового кольца
A2: Фото дефекта (пример) | F2: Причины дефекта | L2: Меры, которые необходимо принять | Q2: Комментарии
F5: Спецификация
F9: Участок резки и экструзии
F19: Участок сборки и вулканизации

Sheet 103
A1: 779 изгиб бортового наполнителя
A2: Фото дефекта (пример) | F2: Причины дефекта | L2: Меры, которые необходимо принять | Q2: Комментарии
F5: Спецификация
F9: Участок резки и экструзии
F19: Участок сборки и вулканизации

Sheet 104
A1: 780 утолщение стыка борта (бортового наполнителя)
A2: Фото дефекта (пример) | F2: Причины дефекта | L2: Меры, которые необходимо принять | Q2: Комментарии
F5: Спецификация
F9: Участок резки и экструзии
F19: Участок сборки и вулканизации

Sheet 105
A1: 781 смещение края "протектор/боковина"
A2: Фото дефекта (пример) | F2: Причины дефекта | L2: Меры, которые необходимо принять | Q2: Комментарии
F5: Спецификация
F9: Участок резки и экструзии
F19: Участок сборки и вулканизации

Sheet 106
A1: 782 облой на протекторе
A2: Фото дефекта (пример) | F2: Причины дефекта | L2: Меры, которые необходимо принять | Q2: Комментарии
F5: Спецификация
F9: Участок резки и экструзии
F19: Участок сборки и вулканизации

Sheet 107
A1: 783 облой на боковине
A2: Фото дефекта (пример) | F2: Причины дефекта | L2: Меры, которые необходимо принять | Q2: Комментарии
F5: Спецификация
F9: Участок резки и экструзии | H9: Завышена толщина Hump SW | L9: Привести контур к номиналу
F19: Участок сборки и вулканизации | H19: 1)контур сырой шины не помещается в пресс форму 2) положение B спейсера на вулканизации меньше ширины полной формовки | L19: 1) расширить ширину полной формовки на сборке. 2)отрегулировать положение B спейсера на вулканизации чтоб его значение было > или = значению полной формовки сборки

Sheet 108
A1: 784 повреждение или отсутствие ламелей
A2: Фото дефекта (пример) | F2: Причины дефекта | L2: Меры, которые необходимо принять | Q2: Комментарии
F5: Спецификация
F9: Участок резки и экструзии
F19: Участок сборки и вулканизации

Sheet 109
A1: 785 открытый стык протектора
A2: Фото дефекта (пример) | F2: Причины дефекта | L2: Меры, которые необходимо принять | Q2: Комментарии
F5: Спецификация
F9: Участок резки и экструзии
F19: Участок сборки и вулканизации

Sheet 110
A1: 786 открытый стык резиновой бортовой ленты
A2: Фото дефекта (пример) | F2: Причины дефекта | L2: Меры, которые необходимо принять | Q2: Комментарии
F5: Спецификация
F9: Участок резки и экструзии
F19: Участок сборки и вулканизации

Sheet 111
A1: 787 увеличение стыка каркаса
A2: Фото дефекта (пример) | F2: Причины дефекта | L2: Меры, которые необходимо принять | Q2: Комментарии
F5: Спецификация
F9: Участок резки и экструзии
F19: Участок сборки и вулканизации

Sheet 112
A1: 788 открытый стык брекера
A2: Фото дефекта (пример) | F2: Причины дефекта | L2: Меры, которые необходимо принять | Q2: Комментарии
F5: Спецификация
F9: Участок резки и экструзии
F19: Участок сборки и вулканизации

Sheet 113
A1: 789 увеличение стыка брекера
A2: Фото дефекта (пример) | F2: Причины дефекта | L2: Меры, которые необходимо принять | Q2: Комментарии
F5: Спецификация
F9: Участок резки и экструзии
F19: Участок сборки и вулканизации

Sheet 114
A1: 790 отклонения при намотке спирального слоя
A2: Фото дефекта (пример) | F2: Причины дефекта | L2: Меры, которые необходимо принять | Q2: Комментарии
F5: Спецификация
F9: Участок резки и экструзии
F19: Участок сборки и вулканизации

Sheet 115
A1: 791 выход корда на протектор
A2: Фото дефекта (пример) | F2: Причины дефекта | L2: Меры, которые необходимо принять | Q2: Комментарии
F5: Спецификация
F9: Участок резки и экструзии
F19: Участок сборки и вулканизации | H19: Недостаточная толщина протектора в зоне HUMP. | L19: Изменить контур протектора. Обратить внимание на бреккер и спиральный слой - возможно деформированы

Sheet 116
A1: 792 облой по линии обода
A2: Фото дефекта (пример) | F2: Причины дефекта | L2: Меры, которые необходимо принять | Q2: Комментарии
F5: Спецификация
F9: Участок резки и экструзии
F19: Участок сборки и вулканизации

Sheet 117
A1: 793 трещина, скол короны - PXR
A2: Фото дефекта (пример) | F2: Причины дефекта | L2: Меры, которые необходимо принять | Q2: Комментарии
F5: Спецификация
F9: Участок резки и экструзии
F19: Участок сборки и вулканизации

Sheet 118
A1: 794 волнообразная неровность на поверхности боковины
A2: Фото дефекта (пример) | F2: Причины дефекта | L2: Меры, которые необходимо принять | Q2: Комментарии
F5: Спецификация
F9: Участок резки и экструзии
F19: Участок сборки и вулканизации

Sheet 0080
A1: 1 | B1: RFV
A2: 2 | B2: LFV
A3: 3 | B3: CON(+)
A4: 4 | B4: CON(-)
A5: 5 | B5: CON(спиральный слой)
A6: 6 | B6: RH1
A7: 7 | B7: RH2
A8: 8 | B8: RH3
A9: 9 | B9: RH4
A10: 10 | B10: RH5
A11: 11 | B11: RH6
A12: 12 | B12: RH7
... A225: 819 | B225: нарушение режима вулканизации (пористость поверхности)
A226: 820
A227: 821 | B227: несоответствие сменной вставки
A228: 822 | B228: легкая шероховатость гермослоя
A229: 823 | B229: нарушение позицирования шины (верх/низ)
A230: 824 | B230: несоответствующая пресс-форма
A231: 825 | B231: прокол диафрагмы
A232: 826 | B232: Повреждение автоматическим обрезчиком (триммером)
A233: 827 | B233: нарушение соосности устройства загрузки
A234: 830 | B234: неполное пятно маркировки (UNIF/BAL)
A235: 831 | B235: зернистая грубая поверхность пресс-формы
A236: 832 | B236: дублирование/нечеткость букв и символов
A237: 833 | B237: повреждение конвейером
A238: 834 | B238: отклонение штампа оператора внешнего осмотра
... A280: 964 | B280: другие (FI)
